<?xml version="1.0" encoding="utf-8"?>
<!-- This URDF was automatically created by SolidWorks to URDF Exporter! Originally created by Stephen Brawner (brawner@gmail.com) 
     Commit Version: 1.6.0-4-g7f85cfe  Build Version: 1.6.7995.38578
     For more information, please see http://wiki.ros.org/sw_urdf_exporter -->
<robot
  name="2dofhover">
  <link
    name="base">
    <inertial>
      <origin
        xyz="-0.016826 -0.080636 0.015707"
        rpy="0 0 0" />
      <mass
        value="1.0757" />
      <inertia
        ixx="0.0049592"
        ixy="1.0436E-07"
        ixz="6.6467E-08"
        iyy="0.0081937"
        iyz="-2.1759E-08"
        izz="0.0049846" />
    </inertial>
    <visual>
      <origin
        xyz="0 0 0"
        rpy="0 0 0" />
      <geometry>
        <mesh
          filename="package://2dofhover/meshes/base.STL" />
      </geometry>
      <material
        name="">
        <color
          rgba="0.74902 0.74902 0.74902 1" />
      </material>
    </visual>
    <collision>
      <origin
        xyz="0 0 0"
        rpy="0 0 0" />
      <geometry>
        <mesh
          filename="package://2dofhover/meshes/base.STL" />
      </geometry>
    </collision>
  </link>
  <link
    name="j1">
    <inertial>
      <origin
        xyz="-0.02174 -0.037566 0.028779"
        rpy="0 0 0" />
      <mass
        value="0.17488" />
      <inertia
        ixx="5.3586E-05"
        ixy="-1.1365E-08"
        ixz="-2.4314E-08"
        iyy="5.0819E-05"
        iyz="-2.0083E-07"
        izz="7.5605E-05" />
    </inertial>
    <visual>
      <origin
        xyz="0 0 0"
        rpy="0 0 0" />
      <geometry>
        <mesh
          filename="package://2dofhover/meshes/j1.STL" />
      </geometry>
      <material
        name="">
        <color
          rgba="0.7451 0.73725 0.72941 1" />
      </material>
    </visual>
    <collision>
      <origin
        xyz="0 0 0"
        rpy="0 0 0" />
      <geometry>
        <mesh
          filename="package://2dofhover/meshes/j1.STL" />
      </geometry>
    </collision>
  </link>
  <joint
    name="joint1"
    type="revolute">
    <origin
      xyz="0 -0.015857 0.082506"
      rpy="-0.0066031 0 0" />
    <parent
      link="base" />
    <child
      link="j1" />
    <axis
      xyz="1 0 0" />
    <limit
      lower="-0.5302"
      upper="0.517"
      effort="0"
      velocity="0" />
  </joint>
  <link
    name="j2">
    <inertial>
      <origin
        xyz="9.8601E-06 -0.0050154 0.067353"
        rpy="0 0 0" />
      <mass
        value="1.2356" />
      <inertia
        ixx="0.013051"
        ixy="-1.6066E-07"
        ixz="-8.5556E-08"
        iyy="0.013043"
        iyz="5.803E-08"
        izz="0.025474" />
    </inertial>
    <visual>
      <origin
        xyz="0 0 0"
        rpy="0 0 0" />
      <geometry>
        <mesh
          filename="package://2dofhover/meshes/j2.STL" />
      </geometry>
      <material
        name="">
        <color
          rgba="0.7451 0.73725 0.72941 1" />
      </material>
    </visual>
    <collision>
      <origin
        xyz="0 0 0"
        rpy="0 0 0" />
      <geometry>
        <mesh
          filename="package://2dofhover/meshes/j2.STL" />
      </geometry>
    </collision>
  </link>
  <joint
    name="joint2"
    type="revolute">
    <origin
      xyz="-0.023721 -0.00066717 0.052996"
      rpy="0 0.10915 3.1416" />
    <parent
      link="j1" />
    <child
      link="j2" />
    <axis
      xyz="0 1 0" />
    <limit
      lower="-0.68636"
      upper="0.4506"
      effort="0"
      velocity="0" />
  </joint>
</robot>